<robot xmlns:xacro="http://www.ros.org/wiki/xacro" name="humanoid_pkg">

  <link
    name="chest_Link">
    <inertial>
      <origin
        xyz="-0.059002 -4.6806E-06 -0.032819"
        rpy="0 0 0" />
      <mass
        value="1.7205" />
      <inertia
        ixx="0.0090608"
        ixy="-1.7864E-07"
        ixz="-5.4617E-07"
        iyy="0.0073219"
        iyz="6.0203E-08"
        izz="0.0046362" />
    </inertial>
    <visual>
      <origin
        xyz="0 0 0"
        rpy="0 0 0" />
      <geometry>
        <mesh
          filename="package://humanoid_pkg/meshes/chest_Link.STL" />
      </geometry>
      <material
        name="">
        <color
          rgba="0.89804 0.91765 0.92941 1" />
      </material>
    </visual>
    <collision>
      <origin
        xyz="0 0 0"
        rpy="0 0 0" />
      <geometry>
        <mesh
          filename="package://humanoid_pkg/meshes/chest_Link.STL" />
      </geometry>
    </collision>
  </link>
  <joint
    name="chest_joint"
    type="fixed">
    <origin
      xyz="0.0589999999999597 0.00499879796810167 0.198863551720086"
      rpy="0 0 0" />
    <parent
      link="waist_Link" />
    <child
      link="chest_Link" />
    <axis
      xyz="0 0 0" />
  </joint>   

   <link
    name="neck_Link">
    <inertial>
      <origin
        xyz="-0.0065711 1.1221E-07 -0.024709"
        rpy="0 0 0" />
      <mass
        value="0.057826" />
      <inertia
        ixx="1.273E-05"
        ixy="5.486E-11"
        ixz="-2.4607E-07"
        iyy="1.3612E-05"
        iyz="-4.3063E-11"
        izz="1.4071E-05" />
    </inertial>
    <visual>
      <origin
        xyz="0 0 0"
        rpy="0 0 0" />
      <geometry>
        <mesh
          filename="package://humanoid_pkg/meshes/neck_Link.STL" />
      </geometry>
      <material
        name="">
        <color
          rgba="0.89804 0.91765 0.92941 1" />
      </material>
    </visual>
    <collision>
      <origin
        xyz="0 0 0"
        rpy="0 0 0" />
      <geometry>
        <mesh
          filename="package://humanoid_pkg/meshes/neck_Link.STL" />
      </geometry>
    </collision>
  </link>
  <joint
    name="neck_joint"
    type="fixed">
    <origin
      xyz="-0.0589999999999757 0 0.172550670854567"
      rpy="0 0 0" />
    <parent
      link="chest_Link" />
    <child
      link="neck_Link" />
    <axis
      xyz="0 0 0" />
  </joint>
  <link
    name="neck_yaw_Link">
    <inertial>
      <origin
        xyz="0.0026021 0.017715 0.019315"
        rpy="0 0 0" />
      <mass
        value="0.084323" />
      <inertia
        ixx="2.4885E-05"
        ixy="1.1417E-06"
        ixz="1.0184E-07"
        iyy="2.2161E-05"
        iyz="-3.6443E-06"
        izz="1.932E-05" />
    </inertial>
    <visual>
      <origin
        xyz="0 0 0"
        rpy="0 0 0" />
      <geometry>
        <mesh
          filename="package://humanoid_pkg/meshes/neck_yaw_Link.STL" />
      </geometry>
      <material
        name="">
        <color
          rgba="0.89804 0.89804 0.89804 1" />
      </material>
    </visual>
    <collision>
      <origin
        xyz="0 0 0"
        rpy="0 0 0" />
      <geometry>
        <mesh
          filename="package://humanoid_pkg/meshes/neck_yaw_Link.STL" />
      </geometry>
    </collision>
  </link>
  <joint
    name="neck_yaw_joint"
    type="revolute">
    <origin
      xyz="0 0 0"
      rpy="0 0 0" />
    <parent
      link="neck_Link" />
    <child
      link="neck_yaw_Link" />
    <axis
      xyz="0 0 1" />
    <limit
      lower="-3.14159"
      upper="3.14159"
      effort="10"
      velocity="1.0" />
  </joint>
  <link
    name="head_Link">
    <inertial>
      <origin
        xyz="0.027551 -0.0041209 0.046161"
        rpy="0 0 0" />
      <mass
        value="0.18871" />
      <inertia
        ixx="0.00064097"
        ixy="4.7808E-07"
        ixz="-1.3992E-06"
        iyy="0.00045607"
        iyz="-1.8574E-06"
        izz="0.00019729" />
    </inertial>
    <visual>
      <origin
        xyz="0 0 0"
        rpy="0 0 0" />
      <geometry>
        <mesh
          filename="package://humanoid_pkg/meshes/head_Link.STL" />
      </geometry>
      <material
        name="">
        <color
          rgba="0.89804 0.91765 0.92941 1" />
      </material>
    </visual>
    <collision>
      <origin
        xyz="0 0 0"
        rpy="0 0 0" />
      <geometry>
        <mesh
          filename="package://humanoid_pkg/meshes/head_Link.STL" />
      </geometry>
    </collision>
  </link>
  <joint
    name="head_joint"
    type="revolute">
    <origin
      xyz="0.0176150000000058 0.00449999999987008 0.0230050000000284"
      rpy="0 0 0" />
    <parent
      link="neck_yaw_Link" />
    <child
      link="head_Link" />
    <axis
      xyz="0 1 0" />
    <limit
      lower="-3.14159"
      upper="3.14159"
      effort="10"
      velocity="1.0" />
  </joint>
  <link
    name="camera_Link">
    <inertial>
      <origin
        xyz="-0.012444 1.1266E-05 -0.00013611"
        rpy="0 0 0" />
      <mass
        value="0.10791" />
      <inertia
        ixx="7.1255E-05"
        ixy="-1.7847E-08"
        ixz="4.9298E-08"
        iyy="7.71E-06"
        iyz="2.4825E-10"
        izz="7.0257E-05" />
    </inertial>
    <visual>
      <origin
        xyz="0 0 0"
        rpy="0 0 0" />
      <geometry>
        <mesh
          filename="package://humanoid_pkg/meshes/camera_Link.STL" />
      </geometry>
      <material
        name="">
        <color
          rgba="0.89804 0.91765 0.92941 1" />
      </material>
    </visual>
    <collision>
      <origin
        xyz="0 0 0"
        rpy="0 0 0" />
      <geometry>
        <mesh
          filename="package://humanoid_pkg/meshes/camera_Link.STL" />
      </geometry>
    </collision>
  </link>
  <joint
    name="camera_joint"
    type="fixed">
    <origin
      xyz="0.0453850000000015 -0.00450000000000009 0.0774061362008152"
      rpy="0 0 0" />
    <parent
      link="head_Link" />
    <child
      link="camera_Link" />
    <axis
      xyz="0 0 0" />
  </joint>
    
</robot>