<robot xmlns:xacro="http://www.ros.org/wiki/xacro" name="humanoid_pkg">
    

    <link
    name="right_hip_roll_Link">
    <inertial>
      <origin
        xyz="-0.027888 0.04083 0.00056004"
        rpy="0 0 0" />
      <mass
        value="1.5469" />
      <inertia
        ixx="0.0028797"
        ixy="-5.658E-05"
        ixz="1.1722E-05"
        iyy="0.00207"
        iyz="2.0467E-05"
        izz="0.0019812" />
    </inertial>
    <visual>
      <origin
        xyz="0 0 0"
        rpy="0 0 0" />
      <geometry>
        <mesh
          filename="package://humanoid_pkg/meshes/right_hip_roll_Link.STL" />
      </geometry>
      <material
        name="">
        <color
          rgba="0.79216 0.81961 0.93333 1" />
      </material>
    </visual>
    <collision>
      <origin
        xyz="0 0 0"
        rpy="0 0 0" />
      <geometry>
        <mesh
          filename="package://humanoid_pkg/meshes/right_hip_roll_Link.STL" />
      </geometry>
    </collision>
  </link>
  <joint
    name="right_hip_roll_joint"
    type="revolute">
    <origin
      xyz="0.0175839596527876 -0.14533051126563 0.0221759352685313"
      rpy="0 0 0" />
    <parent
      link="base_link" />
    <child
      link="right_hip_roll_Link" />
    <axis
      xyz="0 1 0" />
    <limit
      lower="-3.14159"
      upper="3.14159"
      effort="10"
      velocity="1.0" />
  </joint>
  <link
    name="right_hip_pitch_Link">
    <inertial>
      <origin
        xyz="-0.032145 -3.7396E-06 -0.063538"
        rpy="0 0 0" />
      <mass
        value="0.7444" />
      <inertia
        ixx="0.0015527"
        ixy="1.5592E-08"
        ixz="4.0115E-05"
        iyy="0.001194"
        iyz="9.2713E-10"
        izz="0.0009379" />
    </inertial>
    <visual>
      <origin
        xyz="0 0 0"
        rpy="0 0 0" />
      <geometry>
        <mesh
          filename="package://humanoid_pkg/meshes/right_hip_pitch_Link.STL" />
      </geometry>
      <material
        name="">
        <color
          rgba="0.89804 0.91765 0.92941 1" />
      </material>
    </visual>
    <collision>
      <origin
        xyz="0 0 0"
        rpy="0 0 0" />
      <geometry>
        <mesh
          filename="package://humanoid_pkg/meshes/right_hip_pitch_Link.STL" />
      </geometry>
    </collision>
  </link>
  <joint
    name="right_hip_pitch_ joint"
    type="revolute">
    <origin
      xyz="0 0 0"
      rpy="0 0 0" />
    <parent
      link="right_hip_roll_Link" />
    <child
      link="right_hip_pitch_Link" />
    <axis
      xyz="-1 0 0" />
    <limit
      lower="-3.14159"
      upper="3.14159"
      effort="10"
      velocity="1.0" />
  </joint>
  <link
    name="right_hip_yaw_Link">
    <inertial>
      <origin
        xyz="-2.7827E-05 -0.0016262 -0.02388"
        rpy="0 0 0" />
      <mass
        value="1.0856" />
      <inertia
        ixx="0.00071265"
        ixy="1.0046E-07"
        ixz="-1.2697E-07"
        iyy="0.0010508"
        iyz="-1.2277E-06"
        izz="0.00085679" />
    </inertial>
    <visual>
      <origin
        xyz="0 0 0"
        rpy="0 0 0" />
      <geometry>
        <mesh
          filename="package://humanoid_pkg/meshes/right_hip_yaw_Link.STL" />
      </geometry>
      <material
        name="">
        <color
          rgba="0.79216 0.81961 0.93333 1" />
      </material>
    </visual>
    <collision>
      <origin
        xyz="0 0 0"
        rpy="0 0 0" />
      <geometry>
        <mesh
          filename="package://humanoid_pkg/meshes/right_hip_yaw_Link.STL" />
      </geometry>
    </collision>
  </link>
  <joint
    name="right_hip_yaw_joint"
    type="revolute">
    <origin
      xyz="-0.0202000000000037 0 -0.1757"
      rpy="0 0 0" />
    <parent
      link="right_hip_pitch_Link" />
    <child
      link="right_hip_yaw_Link" />
    <axis
      xyz="0 0 -1" />
    <limit
      lower="-3.14159"
      upper="3.14159"
      effort="10"
      velocity="1.0" />
  </joint>
  <link
    name="right_knee_Link">
    <inertial>
      <origin
        xyz="-0.00014239 0.027532 -0.091601"
        rpy="0 0 0" />
      <mass
        value="1.5561" />
      <inertia
        ixx="0.0079264"
        ixy="1.1756E-07"
        ixz="1.3859E-07"
        iyy="0.0078415"
        iyz="0.0005933"
        izz="0.0012684" />
    </inertial>
    <visual>
      <origin
        xyz="0 0 0"
        rpy="0 0 0" />
      <geometry>
        <mesh
          filename="package://humanoid_pkg/meshes/right_knee_Link.STL" />
      </geometry>
      <material
        name="">
        <color
          rgba="0.79216 0.81961 0.93333 1" />
      </material>
    </visual>
    <collision>
      <origin
        xyz="0 0 0"
        rpy="0 0 0" />
      <geometry>
        <mesh
          filename="package://humanoid_pkg/meshes/right_knee_Link.STL" />
      </geometry>
    </collision>
  </link>
  <joint
    name="right_knee_joint"
    type="revolute">
    <origin
      xyz="0 -0.0247000000000758 -0.134300000000004"
      rpy="0 0 0" />
    <parent
      link="right_hip_yaw_Link" />
    <child
      link="right_knee_Link" />
    <axis
      xyz="0 1 0" />
    <limit
      lower="-3.14159"
      upper="3.14159"
      effort="10"
      velocity="1.0" />
  </joint>
  <link
    name="right_ankle_upper_Link">
    <inertial>
      <origin
        xyz="-0.0096451 0.0080178 -0.022594"
        rpy="0 0 0" />
      <mass
        value="0.23217" />
      <inertia
        ixx="0.00017223"
        ixy="-4.2567E-10"
        ixz="-2.6524E-09"
        iyy="0.00015319"
        iyz="-5.3556E-06"
        izz="6.3191E-05" />
    </inertial>
    <visual>
      <origin
        xyz="0 0 0"
        rpy="0 0 0" />
      <geometry>
        <mesh
          filename="package://humanoid_pkg/meshes/right_ankle_upper_Link.STL" />
      </geometry>
      <material
        name="">
        <color
          rgba="0.64706 0.61961 0.58824 1" />
      </material>
    </visual>
    <collision>
      <origin
        xyz="0 0 0"
        rpy="0 0 0" />
      <geometry>
        <mesh
          filename="package://humanoid_pkg/meshes/right_ankle_upper_Link.STL" />
      </geometry>
    </collision>
  </link>
  <joint
    name="right_ankle_upper_joint"
    type="fixed">
    <origin
      xyz="0.02975 0.0246999999992695 -0.104999999999998"
      rpy="0 0 0" />
    <parent
      link="right_knee_Link" />
    <child
      link="right_ankle_upper_Link" />
    <axis
      xyz="0 -1 0" />
    <limit
      lower="-3.14159"
      upper="3.14159"
      effort="10"
      velocity="1.0" />
  </joint>
  <link
    name="right_foot_Link">
    <inertial>
      <origin
        xyz="0.0057978 -5.4386E-10 -0.026004"
        rpy="0 0 0" />
      <mass
        value="0.98973" />
      <inertia
        ixx="0.00050114"
        ixy="2.8848E-11"
        ixz="8.7593E-05"
        iyy="0.0023788"
        iyz="-3.5941E-11"
        izz="0.002753" />
    </inertial>
    <visual>
      <origin
        xyz="0 0 0"
        rpy="0 0 0" />
      <geometry>
        <mesh
          filename="package://humanoid_pkg/meshes/right_foot_Link.STL" />
      </geometry>
      <material
        name="">
        <color
          rgba="0.89804 0.91765 0.92941 1" />
      </material>
    </visual>
    <collision>
      <origin
        xyz="0 0 0"
        rpy="0 0 0" />
      <geometry>
        <mesh
          filename="package://humanoid_pkg/meshes/right_foot_Link.STL" />
      </geometry>
    </collision>
  </link>
  <joint
    name="right_foot_joint"
    type="revolute">
    <origin
      xyz="0.0225 0.0247000000000844 -0.3185"
      rpy="0 0 0" />
    <parent
      link="right_knee_Link" />
    <child
      link="right_foot_Link" />
    <axis
      xyz="0 1 0" />
    <limit
      lower="-3.14159"
      upper="3.14159"
      effort="10"
      velocity="1.0" />
  </joint>
  <link
    name="right_ankle_lower_Link">
    <inertial>
      <origin
        xyz="-0.011288 -0.0067146 -0.012411"
        rpy="0 0 0" />
      <mass
        value="0.2189" />
      <inertia
        ixx="0.00010192"
        ixy="5.8479E-08"
        ixz="5.7528E-08"
        iyy="8.2967E-05"
        iyz="1.9458E-06"
        izz="6.2866E-05" />
    </inertial>
    <visual>
      <origin
        xyz="0 0 0"
        rpy="0 0 0" />
      <geometry>
        <mesh
          filename="package://humanoid_pkg/meshes/right_ankle_lower_Link.STL" />
      </geometry>
      <material
        name="">
        <color
          rgba="0.79216 0.81961 0.93333 1" />
      </material>
    </visual>
    <collision>
      <origin
        xyz="0 0 0"
        rpy="0 0 0" />
      <geometry>
        <mesh
          filename="package://humanoid_pkg/meshes/right_ankle_lower_Link.STL" />
      </geometry>
    </collision>
  </link>
  <joint
    name="right_ankle_lower_joint"
    type="fixed">
    <origin
      xyz="0.02975 0.0247000000000751 -0.169500000000809"
      rpy="0 0 0" />
    <parent
      link="right_knee_Link" />
    <child
      link="right_ankle_lower_Link" />
    <axis
      xyz="0 0 0" />
  </joint>
   
</robot>